Workbook
Name Peso: Reanimación!$B$10

Sheet Medicamentos
A1: Cálculo de medicamentos de alto riesgo | H1: Fecha | I1: =+TODAY() -> 46060
A3: Nombre paciente
A4: Diagnóstico
A5: Fecha de nacimiento | C5: Edad (días) | D5: =(I1-B5) -> 46060 | E5: EG (semanas) | G5: EGC (semanas + días) | I5: =F5+(D5/7) -> 6580 | J5: + | K5: =((F5+(D5/7))-(INT(I5)))*7 -> 0
A6: Peso (g) | B6: 5000 | C6: Talla (cm) | E6: Superficie Corporal (m2) | F6: =(0.05*(B6/1000))+0.05 -> 0.3 | G6: Cupo UCI
A8: Bolos de medicamentos
A9: Información | E9: Cálculo de dosis
A10: Medicamento | B10: Concentración | C10: Vía de administración | D10: Dosis por Kg | E10: Dosis a administrar | G10: Administrar | I10: Diluir en | J10: Tiempo de infusión
A11: Adenosina | B11: 3 mg/ mL | C11: EV | D11: 0,1 mg/Kg | E11: =(0.1*B6)/1000 -> 0.5 | F11: mg | G11: =(E11/3) -> 0.16666667 | H11: mL | I11: No diluir | J11: 1 - 2 seg
A12: Adrenalina | B12: 0,1 mg/mL (1:10.000) | C12: EV | D12: 0,03 mg/Kg | E12: =(0.03*B6)/1000 -> 0.15 | F12: mg | G12: =(E12/0.1) -> 1.5 | H12: mL | I12: SF | J12: Bolo rápido
C13: ET | D13: 0,05 mg/Kg | E13: =(0.05*B6)/1000 -> 0.25 | F13: mg | G13: =(E13/0.1) -> 2.5 | H13: mL
A14: Fenitoína | B14: 5 mg/mL | C14: EV | D14: Carga :20 mg/Kg | E14: =(B6*20)/1000 -> 100 | F14: mg | G14: =(E14/5) -> 20 | H14: mL | I14: SF | J14: 15-30 minutos
D15: Mantención: 3 mg/Kg/dosis | E15: =(B6*3)/1000 -> 15 | F15: mg | G15: =E15/5 -> 3 | H15: mL
A16: Fenobarbital | B16: 10 mg/mL | C16: EV | D16: Carga: 20 mg/Kg | E16: =(B6*20)/1000 -> 100 | F16: mg | G16: =(E16/10) -> 10 | H16: mL | I16: SF | J16: Bolo lento
D17: Mantención: 3 mg/Kg/dosis | E17: =(B6*3)/1000 -> 15 | F17: mg | G17: =(E17/10) -> 1.5 | H17: mL
A18: Fentanilo | B18: 10 mcg / mL | C18: EV | D18: 1 mcg/Kg | E18: =(B6*1)/1000 -> 5 | F18: mcg | G18: =(E18/10) -> 0.5 | H18: mL | I18: SG 5% o SF | J18: Bolo lento
A19: Flumazenil | B19: 100 mcg/mL | C19: EV | D19: 5 mcg/ Kg | E19: =(B6*5)/1000 -> 25 | F19: mcg | G19: =(E19/100) -> 0.25 | H19: mL | I19: SG 5% o SF | J19: 15 segundos
A20: Hidrato de cloral | B20: 100 mg/mL | C20: VO o rectal | D20: 40 mg/ Kg | E20: =(B6*40)/1000 -> 200 | F20: mg | G20: =(E20/100) -> 2 | H20: mL | I20: No dliluir | J20: No aplica
A21: Levetiracetam | B21: 5 mg/mL | C21: EV | D21: Carga: 40 mg/Kg | E21: =(B6*40)/1000 -> 200 | F21: mg | G21: =(E21/5) -> 40 | H21: mL | I21: SG 5% o SF | J21: 15 minutos
D22: Mantención: 40 mg/Kg/dosis | E22: =(B6*40)/1000 -> 200 | F22: mg | G22: =(E22/5) -> 40 | H22: mL
A23: Lorazepam | B23: 2 mg/ mL | C23: EV | D23: 0,05 mg/Kg | E23: =(B6*0.05)/1000 -> 0.25 | F23: mg | G23: =(E23/2) -> 0.125 | H23: mL | I23: No diluir | J23: 15 minutos
A24: Metadona | B24: 1 mg/mL | C24: EV | D24: 0,1 mg/Kg | E24: =(B6*0.1)/1000 -> 0.5 | F24: mg | G24: =(E24/1) -> 0.5 | H24: mL | I24: SF | J24: Bolo rápido
A25: Midazolam | B25: 1 mg/mL | C25: EV | D25: 0,2 mg/ Kg | E25: =(B6*0.2)/1000 -> 1 | F25: mg | G25: =(E25/1) -> 1 | H25: mL | I25: SG 5% o SF | J25: Bolo lento
A26: Morfina | B26: 0,1 mg/0,1mL | C26: EV | D26: 0,1 mg/ Kg | E26: =(B6*0.1)/1000 -> 0.5 | F26: mg | G26: =(E26/0.1) -> 5 | H26: mL | I26: SG 5% o 10% o SF | J26: Bolo lento
A27: Naloxona | B27: 0,4 mg/mL | C27: EV o IM | D27: 0,1 mg/ Kg | E27: =(B6*0.1)/1000 -> 0.5 | F27: mg | G27: =(E27/0.4) -> 1.25 | H27: mL | I27: No diluir | J27: Bolo rapido
A28: Propofol | B28: 2 mg/mL | C28: EV | D28: 1 mg/Kg | E28: =(B6*1)/1000 -> 5 | F28: mg | G28: =(E28/2) -> 2.5 | H28: mL | I28: SG 5% | J28: 60 segundos
A29: Vecuronio | B29: 1 mg/mL | C29: EV | D29: 0,1 mg/ Kg | E29: =(B6*0.1)/1000 -> 0.5 | F29: mg | G29: =(E29/1) -> 0.5 | H29: mL | I29: SF o SG5% | J29: Bolo lento
A31: Infusiones Continuas
A32: Información | D32: Cálculo de dosis
A33: Medicamento | B33: Dosis recomendada | C33: Preparar en | D33: Dosis a utilizar en 1 cc | E33: Unidad de medida | G33: Preparación en 24 mL
A34: Adrenalina | B34: 0,1-1 mcg/Kg/min | C34: SG 5%, 10% o Suero fisiológico | D34: 1 | E34: mcg/Kg/min / mL | G34: =(B6*D34*60*24)/1000/1000 -> 7.2 | H34: mg
A35: Alprostadil (Prostaglandina E1) | B35: 0,01 - 0,1 mcg/Kg/min | C35: SG5% o Suero fisiológico | D35: 0.01 | E35: mcg/Kg/min / mL | G35: =(B6*D35*60*24)/1000 -> 72 | H35: mcg
A36: Dobutamina | B36: 2 - 20 mcg/Kg/min | C36: SG 5%, 10% o Suero fisiológico | D36: 20 | E36: mcg/Kg/min / mL | G36: =(B6*D36*60*24)/1000/1000 -> 144 | H36: mg
A37: Dopamina | B37: 2-20 mcg/Kg/min | C37: SG 5%, 10% o Suero fisiológico | D37: 20 | E37: mcg/Kg/min / mL | G37: =(B6*D37*60*24)/1000/1000 -> 144 | H37: mg
A38: Fentanilo | B38: 0,5- 5 mcg/Kg/hr | C38: SG5% o Suero fisiológico | D38: 5 | E38: mcg/Kg/ hr/mL | G38: =(B6*D38*24)/1000 -> 600 | H38: mcg
A39: Insulina | B39: 0,01 - 0,1 UI/Kg/hr | C39: Suero fisiológico | D39: 0.1 | E39: UI/ Kg/ hr/mL | G39: =(B6*D39*24)/1000 -> 12 | H39: UI
A40: Midazolam | B40: 100 - 200 mcg/Kg/hr | C40: SG5% o Suero fisiológico | D40: 100 | E40: mcg/Kg/ hr/mL | G40: =(B6*D40*24)/1000/1000 -> 12 | H40: mg
A41: Milrinona | B41: 0,3 - 0,75 mcg/Kg/min | C41: SG5% o Suero fisiológico | D41: 1 | E41: mcg/Kg/min / mL | G41: =(B6*60*24*D41)/1000/1000 -> 7.2 | H41: mg
A42: Morfina | B42: 20-40 mcg/Kg/hr | C42: SG 5%, 10% o Suero fisiológico | D42: 20 | E42: mcg/Kg/ hr/mL | G42: =(B6*D42*24)/1000/1000 -> 2.4 | H42: mg
A43: Noradrenalina | B43: 0,1 - 1 mcg/kg/min | C43: Suero glucosado al 5% | D43: 1 | E43: mcg/Kg/min / mL | G43: =(B6*D43*60*24)/1000/1000 -> 7.2 | H43: mg
...

Sheet Antimicrobianos
A1: Cálculo de medicamentos de alto riesgo | H1: Fecha | I1: =+TODAY() -> 46060
A3: Nombre paciente | B3: =Medicamentos!B3 -> 0
A4: Diagnóstico | B4: =Medicamentos!B4 -> 0
A5: Fecha de nacimiento | B5: =Medicamentos!B5 -> 0 | C5: Edad (días) | D5: =Medicamentos!D5 -> 46060 | E5: EG (semanas) | F5: =Medicamentos!F5 -> 0 | G5: EGC (semanas + días) | I5: =Medicamentos!I5 -> 6580 | J5: =Medicamentos!J5 -> + | K5: =Medicamentos!K5 -> 0
A6: Peso (g) | B6: =Medicamentos!B6 -> 5000 | C6: Talla (cm) | D6: =Medicamentos!D6 -> 0 | E6: Superficie Corporal (m2) | F6: =Medicamentos!F6 -> 0.3 | G6: Cupo UCI | I6: =Medicamentos!I6 -> 0
A8: Antibióticos
A9: Información | G9: Cálculo de dosis
A10: Medicamento | B10: Concentración | D10: Vía de administración | E10: Dosis por Kg (mg/Kg/dosis) | G10: Dosis a administrar (mg/dosis) | J10: Intervalo (h) | L10: Administrar (mL) | P10: Diluir en | Q10: Tiempo de infusión
B11: Sin restricción de volumen | C11: Con restricción de volúmen | L11: Sin restricción de volumen | N11: Con restricción de volúmen
A12: Ampicilina | B12: 30 mg/mL | C12: 100 mg/mL | D12: EV | E12: Bacteriemia | F12: Meningitis | G12: Bacteriemia | H12: Meningitis | I12: Unidad de medida | J12: Bacteriemia | K12: Meningitis | L12: Bacteriemia | M12: Meningitis | N12: Bacteriemia | O12: Meningitis | P12: SF | Q12: Bolo directo
E13: =IF(AND(I5<=34,D5<=7),50,IF(AND(I5<=34,D5>=8),75,IF(AND(I5>34,D5<=7),50,IF(AND(I5>34,D5>=8),50,"error")))) -> 50 | F13: =IF(AND(I5<=34,D5<=7),100,IF(AND(I5<=34,D5>=8),75,IF(AND(I5>34,D5<=7),100,IF(AND(I5>34,D5>=8),75,"error")))) -> 75 | G13: =(E13*B6)/1000 -> 250 | H13: =(F13*B6)/1000 -> 375 | I13: mg | J13: =IF(AND(I5<=34,D5<=7),12,IF(AND(I5<=34,D5>=8),12,IF(AND(I5>34,D5<=7),8,IF(AND(I5>34,D5>=8),8,"error")))) -> 8 | K13: =IF(AND(I5<=34,D5<=7),8,IF(AND(I5<=34,D5>=8),6,IF(AND(I5>34,D5<=7),8,IF(AND(I5>34,D5>=8),6,"error")))) -> 6 | L13: =(G13/30) -> 8.3333333 | M13: =(H13/30) -> 12.5 | N13: =(G13/100) -> 2.5 | O13: =(H13/100) -> 3.75
A14: Amikacina | B14: 3 mg/mL | C14: 10 mg/mL | D14: EV | E14: =IF(AND(B6<=800,D5<14),16,IF(AND(B6<=800,D5>=14),20,IF(AND(B6>800,B6<=1200,D5<14),16,IF(AND(B6>800,B6<=1200,D5>=14),20,IF(AND(B6>1200,B6<=2000,D5<14),15,IF(AND(B6>1200,B6<=2000,D5>=14),18,IF(AND(B6>2000,B6<=2800,D5<14),15,IF(AND(B6>2000,B6<=2800,D5>=14),18,IF(AND(B6>2800,D5<14),15,IF(AND(B6>2800,D5>=14),18,"error")))))))))) -> 18 | G14: =(E14*B6)/1000 -> 90 | I14: mg | J14: =IF(AND(B6<=800,D5<14),48,IF(AND(B6<=800,D5>=14),42,IF(AND(B6>800,B6<=1200,D5<14),42,IF(AND(B6>800,B6<=1200,D5>=14),36,IF(AND(B6>1200,B6<=2000,D5<14),36,IF(AND(B6>1200,B6<=2000,D5>=14),30,IF(AND(B6>2000,B6<=2800,D5<14),36,IF(AND(B6>2000,B6<=2800,D5>=14),24,IF(AND(B6>2800,D5<14),30,IF(AND(B6>2800,D5>=14),20,"error")))))))))) -> 20 | L14: =(G14/3) -> 30 | N14: =(G14/10) -> 9 | P14: SF o SG 5, 10 y 20% | Q14: 1 h
A15: Azitromicina EV | B15: 2 mg/mL | D15: EV | E15: 10 | G15: =(E15*B6)/1000 -> 50 | I15: mg | J15: 24 | L15: =(G15/2) -> 25 | P15: API | Q15: 1 h
A16: Azitromicina VO | B16: 200 mg/5mL | D16: VO | L16: =(G15*5)/200 -> 1.25 | Q16: NO APLICA
A17: Cefadroxilo | B17: 250 mg/5mL | D17: VO | E17: Profilaxis ITU | F17: Tratamiento | G17: Profilaxis ITU | H17: Tratamiento | I17: mg | J17: Profilaxis ITU | K17: Tratamiento | L17: Profilaxis ITU | M17: Tratamiento | N17: Profilaxis ITU | O17: Tratamiento | P17: API | Q17: NO APLICA
E18: 20 | F18: 25 | G18: =(E18*B6)/1000 -> 100 | H18: =(F18*B6)/1000 -> 125 | J18: 24 | K18: 12 | L18: =(G18*5)/250 -> 2 | M18: =(H18*5)/250 -> 2.5 | N18: =(G18*5)/250 -> 2 | O18: =(H18*5)/250 -> 2.5
A19: Cefazolina | B19: 20 mg/mL | C19: 100 mg/mL | D19: EV | E19: 25 | G19: =(E19*B6)/1000 -> 125 | I19: mg | J19: =IF(AND(I5<=29,D5<=28),12,IF(AND(I5<=29,D5>28),8,IF(AND(I5>=30,I5<=36,D5<=14),12,IF(AND(I5>=30,I5<=36,D5>14),8,IF(AND(I5>=37,I5<=44,D5<=7),12,IF(AND(I5>=37,I5<=44,D5>7),8,6)))))) -> 6 | L19: =(G19/20) -> 6.25 | N19: =(G19/100) -> 1.25 | P19: SF | Q19: 1 h
A20: Cefepime | B20: 40 mg/mL | D20: EV | E20: Bacteriemia | F20: Meningitis | G20: Bacteriemia | H20: Meningitis | I20: mg | J20: Bacteriemia | K20: Meningitis | L20: Bacteriemia | M20: Meningitis | N20: Bacteriemia | O20: Meningitis | P20: SG 5, 10% o SF | Q20: 30 min
E21: =IF(AND(I5<=36,D5<=28),30,IF(AND(I5>36,D5>28),50)) -> 50 | F21: 50 | G21: =(E21*B6)/1000 -> 250 | H21: =(F21*B6)/1000 -> 250 | J21: 12 | K21: 12 | L21: =(G21/40) -> 6.25 | M21: =(H21/40) -> 6.25 | N21: =(G21/40) -> 6.25 | O21: =(H21/40) -> 6.25
A22: Cefotaxima | B22: 40 mg/mL | D22: EV | E22: Bacteriemia | F22: Meningitis | G22: Bacteriemia | H22: Meningitis | I22: mg | J22: Bacteriemia | K22: Meningitis | L22: Bacteriemia | M22: Meningitis | N22: Bacteriemia | O22: Meningitis | P22: SF | Q22: 1 h
E23: 50 | F23: 50 | G23: =(E23*B6)/1000 -> 250 | H23: =(F23*B6)/1000 -> 250 | J23: =IF(AND(D5<7),12,IF(AND(I5<32,D5>=7),8,IF(AND(I5>=32,D5>=7),6))) -> 6 | K23: =IF(AND(D5<=7),8,IF(AND(D5>=8),6)) -> 6 | L23: =(G23/40) -> 6.25 | M23: =(H23/40) -> 6.25 | N23: =(G23/40) -> 6.25 | O23: =(H23/40) -> 6.25
A24: Ceftazidima | B24: 50 mg/mL | C24: 100 mg/mL | D24: EV | E24: Bacteriemia | F24: Meningitis | G24: Bacteriemia | H24: Meningitis | I24: mg | J24: Bacteriemia | K24: Meningitis | L24: Bacteriemia | M24: Meningitis | N24: Bacteriemia | O24: Meningitis | P24: SG 5, 10% o SF | Q24: 1 h
E25: 30 | F25: 50 | G25: =(E25*B6)/1000 -> 150 | H25: =(F25*B6)/1000 -> 250 | J25: =IF(AND(K5<=29,E5<=28),12,IF(AND(K5<=29,E5>28),8,IF(AND(K5>29,K5<=36,E5<=14),12,IF(AND(K5>29,K5<=36,E5>14),8,IF(AND(K5>36,K5<=44,E5<=7),12,IF(AND(K5>36,K5<=44,E5>7),8,8)))))) -> 8 | K25: =IF(AND(E5<=7),12,IF(AND(E5>=8),8)) -> 8 | L25: =(G25/50) -> 3 | M25: =(H25/50) -> 5 | N25: =(G25/100) -> 1.5 | O25: =(H25/100) -> 2.5
A26: Ciprofloxacino | B26: 2 mg/mL | D26: EV | E26: =IF(AND(I5<=36),10,IF(AND(I5>36),15)) -> 15 | G26: =(E26*B6)/1000 -> 75 | I26: mg | J26: 12 | L26: =(G26/2) -> 37.5 | P26: SG 5, 10% o SF | Q26: 1 h
B27: No aplica | D27: VO | L27: Volumen relacionado a la dosis indicada | P27: API | Q27: NO APLICA
A28: Cloxacilina | B28: 40 mg/mL | C28: 100 mg/mL | D28: EV | E28: Bacteriemia | F28: Meningitis | G28: Bacteriemia | H28: Meningitis | I28: mg | J28: Bacteriemia | K28: Meningitis | L28: Bacteriemia | M28: Meningitis | N28: Bacteriemia | O28: Meningitis | P28: SF | Q28: 30 min
E29: 25 | F29: 50 | G29: =(E29*B6)/1000 -> 125 | H29: =(F29*B6)/1000 -> 250 | J29: =IF(AND(I5<=29,D5<=28),12,IF(AND(I5<=29,I5>28),8,IF(AND(I5>29,I5<=36,D5<=14),12,IF(AND(I5>29,I5<=36,D5>14),8,IF(AND(I5>36,I5<=44,D5<=7),12,IF(AND(I5>36,I5<=44,D5>7),8,6)))))) -> 6 | K29: =IF(AND(I5<=29,D5<=28),12,IF(AND(I5<=29,D5>28),8,IF(AND(I5>29,I5<=36,D5<=14),12,IF(AND(I5>29,I5<=36,D5>14),8,IF(AND(I5>36,I5<=44,D5<=7),12,IF(AND(I5>36,I5<=44,D5>7),8,6)))))) -> 6 | L29: =(G29/40) -> 3.125 | M29: =(H29/40) -> 6.25 | N29: =(G29/100) -> 1.25 | O29: =(H29/100) -> 2.5
A30: Colistin | B30: 10.000 UI/mL | D30: EV | E30: 3 | G30: =(E30*B6)/1000 -> 15 | I30: mg | J30: 8 | L30: =(G30/0.3) -> 50 | P30: SF o SG 5% | Q30: NO APLICA
A31: Cotrimoxazol (en base a trimetoprim) | B31: 0,64 mg/mL | C31: 1,06 mg/mL | D31: EV | E31: Stenotrophomona | F31: Profilaxis ITU | G31: Stenotrophomona | H31: Profilaxis ITU | I31: mg | J31: Stenotrophomona | K31: Profilaxis ITU | L31: Stenotrophomona | M31: Profilaxis ITU | N31: Stenotrophomona | O31: Profilaxis ITU | P31: SF o SG 5% | Q31: 1 h
E32: 5 | F32: 2 | G32: =(E32*B6)/1000 -> 25 | H32: =(F32*B6)/1000 -> 10 | J32: 12 | K32: 24 | L32: =(G32/0.64) -> 39.0625 | M32: =(H32/0.64) -> 15.625 | N32: =(G32/1.06) -> 23.584906 | O32: =(H32/1.06) -> 9.4339623
A33: Ertapenem | B33: 20 mg/mL | D33: EV | E33: 15 | G33: =(E33*B6)/1000 -> 75 | I33: mg | J33: 12 | L33: =(G33/20) -> 3.75 | P33: SF | Q33: 1 h
A34: Gentamicina | B34: 5 mg/mL | C34: 10 mg/mL | D34: EV | E34: 5 | G34: =(E34*B6)/1000 -> 25 | I34: mg | J34: =IF(AND(I5<=29,D5<=7),48,IF(AND(I5<=29,D5>7,D5<=28),36,IF(AND(I5<=29,D5>28),24,IF(AND(I5>29,I5<=34,D5<=7),36,IF(AND(I5>29,D5<=34,D5>7),24,24))))) -> 24 | L34: =(G34/5) -> 5 | N34: =(G34/10) -> 2.5 | P34: SF o SG 5% | Q34: 1 h
A35: Linezolid | B35: 2 mg/mL | D35: EV | E35: 10 | G35: =(E35*B6)/1000 -> 50 | I35: mg | J35: 8 | L35: =(G35/2) -> 25 | P35: SF o SG 5% | Q35: 1 h
A36: Meropenem | B36: 5 mg/mL | C36: 20 mg/mL | D36: EV | E36: Bacteriemia | F36: Meningitis | G36: Bacteriemia | H36: Meningitis | I36: mg | J36: Bacteriemia | K36: Meningitis | L36: Bacteriemia | M36: Meningitis | N36: Bacteriemia | O36: Meningitis | P36: API o SF | Q36: 1 h
E37: =IF(AND(I5>=32,D5>=14),30,20) -> 30 | F37: 40 | G37: =(B6*E37)/1000 -> 150 | H37: =(F37*B6)/1000 -> 200 | J37: =IF(AND(I5<32,D5<=13),12,8) -> 8 | K37: =IF(AND(I5<32,D5<=13),12,8) -> 8 | L37: =(G37/5) -> 30 | M37: =(H37/5) -> 40 | N37: =(G37/20) -> 7.5 | O37: =(H37/20) -> 10
A38: Metronidazol | B38: 5 mg/mL | D38: EV | E38: Carga | F38: Mantención | G38: Carga | H38: Mantención | I38: mg | J38: Carga | K38: Mantención | L38: Carga | M38: Mantención | N38: Carga | O38: Mantención | P38: SF o SG5% | Q38: 1 h
E39: 15 | F39: =IF(AND(K5=26,K5=27),10,7.5) -> 7.5 | G39: =(E39*B6)/1000 -> 75 | H39: =(F39*B6)/1000 -> 37.5 | J39: Por una vez | K39: =IF(AND(I5<=27),24,IF(AND(I5>27,I5<=33),12,IF(AND(I5>33,I5<=40),8,IF(AND(I5>40),6)))) -> 6 | L39: =(G39/5) -> 15 | M39: =(H39/5) -> 7.5 | N39: =L39 -> 15 | O39: =M39 -> 7.5
B40: No aplica | D40: VO | E40: 15 | F40: =IF(AND(K5=26,K5=27),10,7.5) -> 7.5 | G40: =(E40*B6)/1000 -> 75 | H40: =(F40*B6)/1000 -> 37.5 | J40: Por una vez | K40: =IF(AND(I5<=27),24,IF(AND(I5>27,I5<=33),12,IF(AND(I5>33,I5<=40),8,IF(AND(I5>40),6)))) -> 6 | L40: =(G40/5) -> 15 | M40: =(H40/5) -> 7.5 | N40: =L40 -> 15 | O40: =M40 -> 7.5 | P40: API | Q40: NO APLICA
A41: Penicilina G | B41: 50.000 UI/mL | C41: 100.000 UI/mL | D41: EV | E41: Sífilis | G41: Sífilis | I41: UI | J41: Primeros 7 días | K41: Después de 7 días | L41: =(G42/50000) -> 5 | N41: =(G42/100000) -> 2.5 | P41: SG 5% | Q41: 1 h
E42: 50.000 UI | G42: =(50000*B6)/1000 -> 250000 | J42: 12 | K42: 8
...

Sheet Otros medicamentos
A1: Cálculo de medicamentos de alto riesgo | H1: Fecha | I1: =+TODAY() -> 46060
A3: Nombre paciente | B3: =Medicamentos!B3 -> 0
A4: Diagnóstico | B4: =Medicamentos!B4 -> 0
A5: Fecha de nacimiento | B5: =Medicamentos!B5 -> 0 | C5: Edad (días) | E5: EG (semanas) | F5: =Medicamentos!F5 -> 0 | G5: EGC (semanas + días) | I5: =F5+(D5/7) -> 0 | J5: + | K5: =((F5+(D5/7))-(INT(I5)))*7 -> 0
A6: Peso (g) | B6: 800 | C6: Talla (cm) | D6: 34 | E6: Superficie Corporal (m2) | F6: =+((B6/1000*4)+7)/(90+B6/1000) -> 0.1123348
A8: Bolos de medicamentos
A9: Información | E9: Cálculo de dosis
A10: Medicamento | B10: Concentración | C10: Vía de administración | D10: Dosis por Kg | E10: Dosis a administrar | G10: Administrar | I10: Diluir en | J10: Tiempo de infusión
A11: Albúmina | B11: 20% (20g/100 mL) | C11: EV | D11: 1g/Kg | E11: =(1*B6)/1000 -> 0.8 | F11: g | G11: =(E11*100)/20 -> 4 | H11: mL | I11: API | J11: 4-6 Hr
A12: Amiodarona | B12: 1,5 mg/mL | C12: EV | D12: 5 mg/Kg | E12: =(B6*5)/1000 -> 4 | F12: mg | G12: =(E12/1.5) -> 2.6666667 | H12: mL | I12: SG 5% o SF | J12: 20 - 60 min
A13: Atropina | B13: 0,1 mg/mL | C13: EV | D13: 0,01 mg/Kg | E13: =(B6*0.01)/1000 -> 0.008 | F13: mg | G13: =(E13/0.1) -> 0.08 | H13: mL | I13: SG 5% o SF | J13: Bolo rápido
A14: Gluconato de calcio | B14: 50 mg/mL (al medio) | C14: EV por vía central | D14: 100 mg/Kg | E14: =(B6*100)/1000 -> 80 | F14: mg | G14: =(E14/50) -> 1.6 | H14: mL | I14: API | J14: Bolo lento
A15: Sulfato de magnesio | B15: 100 mg/mL | C15: EV | D15: 25 mg/Kg | E15: =(B6*25)/1000 -> 20 | F15: mg | G15: =(E15/100) -> 0.2 | H15: mL | I15: SG 5% o SF | J15: Bolo rápido
A16: Verapamilo | B16: 0,5 mg/mL | C16: EV | D16: 0,1 mg/Kg | E16: =(B6*0.1)/1000 -> 0.08 | F16: mg | G16: =(E16/0.5) -> 0.16 | H16: mL | I16: SG 5% | J16: Bolo lento
A18: Infusiones Continuas
A19: Información | D19: Cálculo de dosis
A20: Medicamento | B20: Dosis recomendada | C20: Preparar en | D20: Dosis a utilizar en 1 cc | E20: Unidad de medida | G20: Preparación en 24 mL
A21: Amiodarona | B21: 7-15 mcg/Kg/min | C21: SG5% o SF | D21: 15 | E21: mcg/Kg/min/mL | G21: =(B6*D21*24*60)/1000/1000 -> 17.28 | H21: mg
A22: Ketamina | B22: 10-40 mcg/Kg/min | C22: SG5% o SF | D22: 15 | E22: mcg/Kg/min/mL | G22: =(B6*D22*24*60)/1000/1000 -> 17.28 | H22: mg
A23: Furosemida | B23: 0.05-1 mg/Kg/h | C23: SF | D23: 1 | E23: mg/Kg/h/mL | G23: =(B6*D23*24)/1000 -> 19.2 | H23: mg
A24: Isoproterenol | B24: 0.05-0,5 mcg/Kg/min | C24: SF | D24: 0.1 | E24: mcg/Kg/min/mL | G24: =(B6*D24*24*60)/1000/1000 -> 0.1152 | H24: mg
A25: Vasopresina | B25: 0.1-1,2 mU/Kg/min | C25: SG5% o SF | D25: 1 | E25: mUI/Kg/min/mL | G25: =(B6*D25*24*60)/1000/1000 -> 1.152 | H25: UI

Sheet Inmunoglobulina
A1: Cálculo de medicamentos de alto riesgo | H1: Fecha | I1: =+TODAY() -> 46060
A3: Nombre paciente | B3: =Medicamentos!B3 -> 0
A4: Diagnóstico | B4: =Medicamentos!B4 -> 0
A5: Fecha de nacimiento | B5: =Medicamentos!B5 -> 0 | C5: Edad (días) | D5: =Medicamentos!D5 -> 46060 | E5: EG (semanas) | F5: =Medicamentos!F5 -> 0 | G5: EGC (semanas + días) | I5: =Medicamentos!I5 -> 6580 | J5: =Medicamentos!J5 -> + | K5: =Medicamentos!K5 -> 0
A6: Peso (g) | B6: =Medicamentos!B6 -> 5000 | C6: Talla (cm) | D6: =Medicamentos!D6 -> 0 | E6: SC(m2) | F6: =Medicamentos!F6 -> 0.3 | G6: Cupo UCI | I6: =Medicamentos!I6 -> 0 | O6: 5000
O7: 10000
A9: Inmunoglobulina EV
A10: Información | E10: Cálculo de dosis | I10: Velocidad de infusión (mL/H) | K10: Tiempo total de infusión (H)
A11: Medicamento | B11: Presentación en 100 mL (mg) | C11: Vía de administración | D11: Dosis por Kg (en mg) | E11: Dosis a administrar | G11: Volumen total a administrar | I11: Primeros 60 min | J11: Horas posteriores | O11: 400
A12: Inmunoglobulina EV | B12: 10000 | C12: EV | D12: 400 | E12: =(B6*D12)/1000 -> 2000 | F12: mg | G12: =(E12*100)/B12 -> 20 | H12: mL | I12: =+IF(AND(B12=5000,OR(D12=400,D12=500)),0.015*B6*60/1000,IF(AND(B12=5000,D12=1000),0.03*B6*60/1000,IF(AND(B12=10000,OR(D12=400,D12=500)),0.007*B6*60/1000,IF(AND(B12=10000,D12=1000),0.01*B6*60/1000,"ERROR")))) -> 2.1 | J12: =+IF(AND(B12=5000,OR(D12=400,D12=500)),0.04*B6*60/1000,IF(AND(B12=5000,D12=1000),0.06*B6*60/1000,IF(AND(B12=10000,OR(D12=400,D12=500)),0.02*B6*60/1000,IF(AND(B12=10000,D12=1000),0.03*B6*60/1000,"ERROR")))) -> 6 | O12: 500
O13: 1000
A15: Control de signos vitales
A16: Hora | B16: PA | C16: PAM | D16: FC | E16: FR | F16: SAT. O2 | G16: Tº
A17: 0
A19: 0.5
A21: 1
A23: Si paciente tolera bien la primera hora, subir goteo según volumen de horas posteriores
A24: 2
A26: 3
A28: 4
A30: 5
A32: 6
A34: En caso de que aparezcan reacciones adversas, disminuir la velocidad de infusión o suspender
B37: Información adicional
B38: Vía de administración (vía exclusiva) | C38: central | D38: periferica
B39: Fecha de vencimiento
B40: Lote
A43: Observaciones
A54: Firma Médico Tratante | E54: Firma Matron/a encargado/a

Sheet Reanimación
A1: Cálculo de medicamentos de alto riesgo | H1: Fecha | I1: =+TODAY() -> 46060
A3: Nombre paciente | B3: =Medicamentos!B3 -> 0
A4: Diagnóstico | B4: =Medicamentos!B4 -> 0
A5: Fecha de nacimiento | B5: =Medicamentos!B5 -> 0 | C5: Edad (días) | D5: =(I1-B5) -> 46060 | E5: EG (semanas) | F5: =Medicamentos!F5 -> 0 | G5: EGC (semanas + días) | I5: =F5+(D5/7) -> 6580 | J5: + | K5: =((F5+(D5/7))-(INT(I5)))*7 -> 0
A6: Peso (g) | B6: =Medicamentos!B6 -> 5000 | C6: Talla (cm) | D6: =Medicamentos!D6 -> 0 | E6: Superficie Corporal (m2) | F6: =(0.05*(B6/1000))+0.05 -> 0.3
A12: Nº TET (DI) | B12: =IF(B6>2000,3.5,IF(B6<1000,2.5,3)) -> 3.5 | C12: mm
A13: Dist. Boca | B13: =(B6/1009)+6 -> 10.955401 | C13: cm
B16: 1a (0,5 j/kg) | C16: 2a (2 j/kg)
A17: Cardioversión (Sincronizada) | B17: =0.5*B6/1000 -> 2.5 | C17: =2*B6/1000 -> 10 | D17: Joules

Sheet Versión Para Imprimir
B2: Calculadora Medicamentos UCI
A4: Nombre paciente | B4: =Medicamentos!B3 -> 0
A5: Peso (g) | B5: =Medicamentos!B6 -> 5000 | F5: Fecha | G5: =Medicamentos!I1 -> 46060
A7: Bolos de medicamentos
A8: Medicamentos | B8: Dosis a administrar (mg) | D8: Administrar (mL) | F8: Diluir en | G8: Tiempo de infusión
A9: Adenosina | B9: =Medicamentos!E11 -> 0.5 | D9: =Medicamentos!G11 -> 0.16666667 | F9: No diluir | G9: 1-2 seg
A10: Adrenalina | B10: =Medicamentos!E12 -> 0.15 | D10: =Medicamentos!G12 -> 1.5 | F10: SF | G10: Bolo rápido
A11: Fenitoína | B11: =Medicamentos!E14 -> 100 | C11: Carga | D11: =Medicamentos!G13 -> 2.5 | F11: SF | G11: 15-30 minutos
B12: =Medicamentos!E15 -> 15 | C12: Mantención | D12: =Medicamentos!G15 -> 3
A13: Fenobarbital | B13: =Medicamentos!E16 -> 100 | C13: Carga | D13: =Medicamentos!G16 -> 10 | F13: SF | G13: Bolo lento
B14: =Medicamentos!E17 -> 15 | C14: Mantención | D14: =Medicamentos!G17 -> 1.5
A15: Fentanilo | B15: =Medicamentos!E18 -> 5 | C15: gamma | D15: =Medicamentos!G18 -> 0.5 | F15: SG 5% o SF | G15: Bolo lento
A16: Flumazenil | B16: =Medicamentos!E19 -> 25 | C16: mcg | D16: =Medicamentos!G19 -> 0.25 | F16: SG 5% o SF | G16: 15 seg
A17: Hidrato de cloral | B17: =Medicamentos!E20 -> 200 | D17: =Medicamentos!G20 -> 2 | F17: No dliluir | G17: No aplica
A18: Levetiracetam | B18: =Medicamentos!E21 -> 200 | C18: Carga | D18: =Medicamentos!G21 -> 40 | F18: SG 5% o SF | G18: 15 minutos
B19: =Medicamentos!E22 -> 200 | C19: Mantención | D19: =Medicamentos!G22 -> 40
A20: Lorazepam | B20: =Medicamentos!E23 -> 0.25 | D20: =Medicamentos!G23 -> 0.125 | F20: No diluir | G20: 15 minutos
A21: Metadona | B21: =Medicamentos!E24 -> 0.5 | D21: =Medicamentos!G24 -> 0.5 | F21: SF | G21: Bolo rápido
A22: Midazolam | B22: =Medicamentos!E25 -> 1 | D22: =Medicamentos!G25 -> 1 | F22: SG 5% o SF | G22: Bolo lento
A23: Morfina | B23: =Medicamentos!E26 -> 0.5 | D23: =Medicamentos!G26 -> 5 | F23: SG 5% o 10% o SF | G23: Bolo lento
A24: Naloxona | B24: =Medicamentos!E27 -> 0.5 | D24: =Medicamentos!G27 -> 1.25 | F24: No diluir | G24: Bolo rapido
A25: Propofol | B25: =Medicamentos!E28 -> 5 | D25: =Medicamentos!G28 -> 2.5 | F25: SG 5% | G25: 60 segundos
A26: Vecuronio | B26: =Medicamentos!E29 -> 0.5 | D26: =Medicamentos!G29 -> 0.5 | F26: 10 mL API | G26: Bolo lento
A29: Infusiones Continuas
A30: Medicamentos | B30: Dosis en 1 cc | D30: Unidad de medida | F30: Preparación en 24 mL
A31: Adrenalina | B31: =Medicamentos!D34 -> 1 | D31: mcg/Kg/min/mL | F31: =Medicamentos!G34 -> 7.2 | H31: mg
A32: Alprostadil (Prostaglandina) | B32: =Medicamentos!D35 -> 0.01 | D32: mcg/Kg/min/mL | F32: =Medicamentos!G35 -> 72 | H32: mcg
A33: Dobutamina | B33: =Medicamentos!D36 -> 20 | D33: mcg/Kg/min/mL | F33: =Medicamentos!G36 -> 144 | H33: mg
A34: Dopamina | B34: =Medicamentos!D37 -> 20 | D34: mcg/Kg/min/mL | F34: =Medicamentos!G37 -> 144 | H34: mg
A35: Fentanilo | B35: =Medicamentos!D38 -> 5 | D35: gamma/Kg/ hr/mL | F35: =Medicamentos!G38 -> 600 | H35: mcg
A36: Insulina | B36: =Medicamentos!D39 -> 0.1 | D36: UI/ Kg/ hr/mL | F36: =Medicamentos!G39 -> 12 | H36: UI
A37: Midazolam | B37: =Medicamentos!D40 -> 100 | D37: mcg/Kg/ hr/mL | F37: =Medicamentos!G40 -> 12 | H37: mg
A38: Milrinona | B38: =Medicamentos!D41 -> 1 | D38: mcg/Kg/min/mL | F38: =Medicamentos!G41 -> 7.2 | H38: mg
A39: Morfina | B39: =Medicamentos!D42 -> 20 | D39: mcg/Kg/ hr/mL | F39: =Medicamentos!G42 -> 2.4 | H39: mg
A40: Noradrenalina | B40: =Medicamentos!D43 -> 1 | D40: mcg/Kg/min/mL | F40: =Medicamentos!G43 -> 7.2 | H40: mg
A41: Precedex (dexmedetomidina) | B41: =Medicamentos!D44 -> 0.6 | D41: mcg/Kg/ hr/mL | F41: =Medicamentos!G44 -> 72 | H41: mcg
A42: Propofol | B42: =Medicamentos!D45 -> 3 | D42: mcg/Kg/ hr/mL | F42: =Medicamentos!G45 -> 360 | H42: mg
A43: Vecuronio | B43: =Medicamentos!D46 -> 0.2 | D43: mcg/Kg/ hr/mL | F43: =Medicamentos!G46 -> 24 | H43: mg
D45: CUPO UCI | E45: =Medicamentos!I6 -> 0
